Workbook

Sheet Read Me
B2: Databricks SDP (Lakeflow Declarative Pipelines) — Medallion Cost Model
B3: Batch vs. Continuous compute cost estimate across Bronze / Silver / Gold layers
B5: How this workbook is built
B6: This is a planning-grade estimate built on Databricks TYPICAL / LIST pricing (public rate cards), not an
B7: invoice reconciliation. No account-specific compute notes were provided, so every rate and every sizing
B8: assumption below is an editable input — replace the blue cells with your negotiated DBU rates and your
B9: own cluster sizing once you have them, and every downstream formula recalculates automatically.
B11: Cost = (DBU platform fee) + (underlying cloud VM infrastructure cost). Databricks bills the DBU fee;
B12: AWS/Azure/GCP separately bills the VM the cluster runs on. Both are modeled here.
B14: Batch mode = Jobs Compute / SDP triggered pipelines that run on a schedule, then shut down.
B15: Continuous mode = SDP pipelines (or Structured Streaming) left running 24/7 to process data with low latency.
B17: Tabs
B18: Assumptions | C18: Editable DBU rates, VM instance costs, and per-layer sizing inputs (all blue).
B19: Batch Mode | C19: Monthly cost for Bronze/Silver/Gold run as scheduled/triggered SDP pipelines.
B20: Continuous Mode | C20: Monthly cost for Bronze/Silver/Gold run as always-on SDP pipelines.
B21: Summary | C21: Side-by-side comparison, savings, and a chart.
B22: Feeding the model from your actual system.billing.usage data
B23: The "Billing Usage Import" tab has two ready-to-run SQL queries against system.billing.usage (+ list_prices)
B24: that pull your real effective $/DBU by workload and real DBU/hr by node type. Paste the results into that tab, | C24: Blue text — hardcoded input. Edit freely; this is the number that drives the model.
B25: then set Assumptions!C65 to "Actual Billing". Every rate/DBU cell falls back to list price automatically for | C25: Black text — formula. Don't overtype; change the blue inputs that feed it instead.
B26: any row you have not filled in yet, so you can mix real and estimated numbers as your data fills in. | C26: Green text — link to another tab.
B27: Sample | C27: Yellow fill — key assumption worth double-checking against your own contract/rate card.
B29: Sources for the default list-price assumptions
B30: Databricks Jobs Compute / SDP / Serverless DBU rates: Databricks public pricing pages and 2026 third-party
B31: pricing guides (AWS, Premium/Enterprise tier, US regions). Rates vary by cloud, region, tier, and any
B32: committed-use discount — confirm current figures at databricks.com/product/pricing before budgeting.
B33: Underlying VM cost and DBU-per-node consumption: AWS EC2 on-demand list pricing and Databricks' published
B34: DBU-per-instance-type tables (e.g., m5.xlarge ≈ 0.69 DBU/hr). Verify at the Databricks pricing calculator:
B35: databricks.com/product/pricing/product-pricing/instance-types
B36: Runtime/frequency/node-count assumptions per medallion layer are illustrative starting points, not
B37: measured values — replace them with your own pipeline telemetry (job run history, cluster metrics) for
B38: an accurate estimate.

Sheet Assumptions
B2: 1. Databricks DBU Rates (list pricing, USD, AWS Premium/Enterprise tier)
B4: Compute Type | C4: $ / DBU | D4: Notes | F4: List $/DBU
B5: Jobs Compute (Classic) — batch/triggered | C5: =IF(AND($C$64="Actual Billing",ISNUMBER('Billing Usage Import'!$E$31)),'Billing Usage Import'!$E$31,F5) -> 0.15 | D5: Cheapest classic SKU; used for scheduled/triggered pipelines. | F5: 0.15
B6: All-Purpose Compute (Classic) — interactive, reference only | C6: 0.4 | D6: Interactive notebooks; not used for production pipelines in this model.
B7: SDP Classic — Core | C7: 0.2 | D7: Lakeflow Declarative Pipelines, classic compute, Core product edition.
B8: SDP Classic — Pro / Advanced | C8: 0.3 | D8: Adds data quality expectations / change data capture features.
B9: SDP Serverless — Standard | C9: =IF(AND($C$64="Actual Billing",ISNUMBER('Billing Usage Import'!$E$32)),'Billing Usage Import'!$E$32,F9) -> 0.35 | D9: Fully managed; used here as the default rate for Continuous mode. | F9: 0.35
B10: SDP Serverless — Performance Optimized | C10: 0.35 | D10: Same list $/DBU as Standard, but consumes more DBU/hr for faster startup/throughput.
B12: 2. Cluster Node Types — 4 size tiers (DBU consumption & underlying cloud VM cost, on-demand)
B14: Tier Label | C14: Instance Type | D14: DBU / hr / node | E14: VM $ / hr / node (cloud infra) | F14: vCPU / node | G14: RAM (GB) / node
B15: Small | C15: =IF($C$20="AWS",$C$41,IF($C$21="E-series (memory optimized)",$C$55,$C$48)) -> m5.xlarge | D15: =IF($C$20="AWS",$F$41,IF($C$21="E-series (memory optimized)",$F$55,$F$48)) -> 0.69 | E15: =IF($C$20="AWS",$G$41,IF($C$21="E-series (memory optimized)",$G$55,$G$48)) -> 0.192 | F15: =IF($C$20="AWS",$D$41,IF($C$21="E-series (memory optimized)",$D$55,$D$48)) -> 4 | G15: =IF($C$20="AWS",$E$41,IF($C$21="E-series (memory optimized)",$E$55,$E$48)) -> 16
B16: Medium | C16: =IF($C$20="AWS",$C$42,IF($C$21="E-series (memory optimized)",$C$56,$C$49)) -> m5.2xlarge | D16: =IF($C$20="AWS",$F$42,IF($C$21="E-series (memory optimized)",$F$56,$F$49)) -> 1.38 | E16: =IF($C$20="AWS",$G$42,IF($C$21="E-series (memory optimized)",$G$56,$G$49)) -> 0.384 | F16: =IF($C$20="AWS",$D$42,IF($C$21="E-series (memory optimized)",$D$56,$D$49)) -> 8 | G16: =IF($C$20="AWS",$E$42,IF($C$21="E-series (memory optimized)",$E$56,$E$49)) -> 32
B17: Large | C17: =IF($C$20="AWS",$C$43,IF($C$21="E-series (memory optimized)",$C$57,$C$50)) -> r5.4xlarge | D17: =IF($C$20="AWS",$F$43,IF($C$21="E-series (memory optimized)",$F$57,$F$50)) -> 3.6 | E17: =IF($C$20="AWS",$G$43,IF($C$21="E-series (memory optimized)",$G$57,$G$50)) -> 1.008 | F17: =IF($C$20="AWS",$D$43,IF($C$21="E-series (memory optimized)",$D$57,$D$50)) -> 16 | G17: =IF($C$20="AWS",$E$43,IF($C$21="E-series (memory optimized)",$E$57,$E$50)) -> 128
B18: XLarge | C18: =IF($C$20="AWS",$C$44,IF($C$21="E-series (memory optimized)",$C$58,$C$51)) -> r5.8xlarge | D18: =IF($C$20="AWS",$F$44,IF($C$21="E-series (memory optimized)",$F$58,$F$51)) -> 7.2 | E18: =IF($C$20="AWS",$G$44,IF($C$21="E-series (memory optimized)",$G$58,$G$51)) -> 2.016 | F18: =IF($C$20="AWS",$D$44,IF($C$21="E-series (memory optimized)",$D$58,$D$51)) -> 32 | G18: =IF($C$20="AWS",$E$44,IF($C$21="E-series (memory optimized)",$E$58,$E$51)) -> 256
B20: Cloud | C20: AWS | D20: Pick from the dropdown. Drives every Small/Medium/Large/XLarge row above and all downstream sheets.
B21: Azure VM Series (used only if Cloud = Azure) | C21: D-series (general purpose) | D21: D-series = balanced ETL. E-series = memory-optimized (wide joins, shuffles, caching).
B23: Lookup range used by Batch/Continuous/B2S tabs: Assumptions!$B$15:$G$18
B25: 3. Rate Selection by Pipeline Mode
B27: Mode | C27: DBU Rate Used | D27: $ / DBU (linked)
B28: Batch / Triggered | C28: Jobs Compute (Classic) | D28: =C5 -> 0.15
B29: Continuous / Streaming (SDP Serverless) | C29: SDP Serverless (Standard) | D29: =C9 -> 0.35
B30: Continuous (Jobs Compute) | C30: Jobs Compute (Classic) | D30: =C5 -> 0.15
B32: “Continuous (Jobs Compute)” models a streaming/always-on pipeline running on classic Jobs Compute instead of SDP Serverless — cheaper $/DBU, but you manage autoscaling yourself instead of Databricks doing it. Change any D-column formula above to point at a different rate row to re-run every downstream number.
B34: 4. Per-Layer Sizing Inputs — edit these to reflect your real pipelines
B35: Defaults on the Batch Mode / Continuous Mode tabs are illustrative starting points — replace with your own job history.
B37: 2b. Raw Node Specs by Cloud / Series (4 size tiers — edit rates here; the active table above pulls from your Cloud/Series selection)
B39: AWS
B40: Tier | C40: Instance Type | D40: vCPU | E40: RAM (GB) | F40: DBU/hr/node | G40: VM $/hr/node
B41: Small | C41: m5.xlarge | D41: 4 | E41: 16 | F41: =IF($C$64<>"Actual Billing",H41,IFERROR(IF(ISNUMBER(INDEX('Billing Usage Import'!$E$39:$E$50,MATCH($C41,'Billing Usage Import'!$B$39:$B$50,0))),INDEX('Billing Usage Import'!$E$39:$E$50,MATCH($C41,'Billing Usage Import'!$B$39:$B$50,0)),H41),H41)) -> 0.69 | G41: 0.192 | H41: 0.69
B42: Medium | C42: m5.2xlarge | D42: 8 | E42: 32 | F42: =IF($C$64<>"Actual Billing",H42,IFERROR(IF(ISNUMBER(INDEX('Billing Usage Import'!$E$39:$E$50,MATCH($C42,'Billing Usage Import'!$B$39:$B$50,0))),INDEX('Billing Usage Import'!$E$39:$E$50,MATCH($C42,'Billing Usage Import'!$B$39:$B$50,0)),H42),H42)) -> 1.38 | G42: 0.384 | H42: 1.38
B43: Large | C43: r5.4xlarge | D43: 16 | E43: 128 | F43: =IF($C$64<>"Actual Billing",H43,IFERROR(IF(ISNUMBER(INDEX('Billing Usage Import'!$E$39:$E$50,MATCH($C43,'Billing Usage Import'!$B$39:$B$50,0))),INDEX('Billing Usage Import'!$E$39:$E$50,MATCH($C43,'Billing Usage Import'!$B$39:$B$50,0)),H43),H43)) -> 3.6 | G43: 1.008 | H43: 3.6
B44: XLarge | C44: r5.8xlarge | D44: 32 | E44: 256 | F44: =IF($C$64<>"Actual Billing",H44,IFERROR(IF(ISNUMBER(INDEX('Billing Usage Import'!$E$39:$E$50,MATCH($C44,'Billing Usage Import'!$B$39:$B$50,0))),INDEX('Billing Usage Import'!$E$39:$E$50,MATCH($C44,'Billing Usage Import'!$B$39:$B$50,0)),H44),H44)) -> 7.2 | G44: 2.016 | H44: 7.2
B46: Azure D-series (Ddsv5) — general purpose, balanced CPU:RAM (~4 GB/vCPU), local NVMe temp disk. Good default for typical ETL.
B47: Tier | C47: Instance Type | D47: vCPU | E47: RAM (GB) | F47: DBU/hr/node | G47: VM $/hr/node
B48: Small | C48: Standard_D4ds_v5 | D48: 4 | E48: 16 | F48: =IF($C$64<>"Actual Billing",H48,IFERROR(IF(ISNUMBER(INDEX('Billing Usage Import'!$E$39:$E$50,MATCH($C48,'Billing Usage Import'!$B$39:$B$50,0))),INDEX('Billing Usage Import'!$E$39:$E$50,MATCH($C48,'Billing Usage Import'!$B$39:$B$50,0)),H48),H48)) -> 1 | G48: 0.211 | H48: 1
B49: Medium | C49: Standard_D8ds_v5 | D49: 8 | E49: 32 | F49: =IF($C$64<>"Actual Billing",H49,IFERROR(IF(ISNUMBER(INDEX('Billing Usage Import'!$E$39:$E$50,MATCH($C49,'Billing Usage Import'!$B$39:$B$50,0))),INDEX('Billing Usage Import'!$E$39:$E$50,MATCH($C49,'Billing Usage Import'!$B$39:$B$50,0)),H49),H49)) -> 2 | G49: 0.422 | H49: 2
B50: Large | C50: Standard_D16ds_v5 | D50: 16 | E50: 64 | F50: =IF($C$64<>"Actual Billing",H50,IFERROR(IF(ISNUMBER(INDEX('Billing Usage Import'!$E$39:$E$50,MATCH($C50,'Billing Usage Import'!$B$39:$B$50,0))),INDEX('Billing Usage Import'!$E$39:$E$50,MATCH($C50,'Billing Usage Import'!$B$39:$B$50,0)),H50),H50)) -> 4 | G50: 0.845 | H50: 4
B51: XLarge | C51: Standard_D32ds_v5 | D51: 32 | E51: 128 | F51: =IF($C$64<>"Actual Billing",H51,IFERROR(IF(ISNUMBER(INDEX('Billing Usage Import'!$E$39:$E$50,MATCH($C51,'Billing Usage Import'!$B$39:$B$50,0))),INDEX('Billing Usage Import'!$E$39:$E$50,MATCH($C51,'Billing Usage Import'!$B$39:$B$50,0)),H51),H51)) -> 8 | G51: 1.69 | H51: 8
B53: Azure E-series (Edsv5) — memory-optimized (~8 GB/vCPU), local NVMe temp disk. Use for wide joins, large shuffles, or heavy caching in Silver/Gold.
B54: Tier | C54: Instance Type | D54: vCPU | E54: RAM (GB) | F54: DBU/hr/node | G54: VM $/hr/node
...

Sheet Billing Usage Import
B2: Billing Usage Import — Actual system.billing.usage Data
B3: Run the two queries below in Databricks SQL, then paste the results into the tables in sections 3 & 4.
B5: 1. SQL — Effective $/DBU by Workload (last 90 days)
B6: SELECT CASE WHEN u.sku_name LIKE '%JOBS_COMPUTE%' AND u.sku_name NOT LIKE '%SERVERLESS%' THEN 'Batch / Triggered' WHEN u.sku_name LIKE '%SERVERLESS%' OR u.sku_name LIKE '%LAKEFLOW%' OR u.sku_name LIKE '%DLT%' THEN 'Continuous / Streaming' ELSE 'Other' END AS mode, SUM(u.usage_quantity) AS total_dbus, SUM(u.usage_quantity * lp.pricing.default) AS total_dbu_dollars, SUM(u.usage_quantity * lp.pricing.default) / NULLIF(SUM(u.usage_quantity),0) AS effective_dollar_per_dbu FROM system.billing.usage u JOIN system.billing.list_prices lp ON u.sku_name = lp.sku_name AND u.usage_start_time >= lp.price_start_time AND (u.usage_start_time < lp.price_end_time OR lp.price_end_time IS NULL) WHERE u.usage_date >= DATE_SUB(CURRENT_DATE(), 90) GROUP BY 1 ORDER BY 1;
B15: Note: filter/GROUP BY logic reflects typical sku_name conventions as of 2026 — validate against your own workspace's system.billing.usage.sku_name values before relying on it (some accounts use slightly different SKU strings, e.g. STANDARD_ vs PREMIUM_ vs ENTERPRISE_ prefixes).
B18: 2. SQL — DBU/hr by Node/Instance Type (last 90 days)
B19: SELECT u.usage_metadata.node_type AS instance_type, SUM(u.usage_quantity) AS total_dbus, SUM(DATEDIFF(SECOND, u.usage_start_time, u.usage_end_time)) / 3600.0 AS total_node_hours, SUM(u.usage_quantity) / NULLIF(SUM(DATEDIFF(SECOND, u.usage_start_time, u.usage_end_time)) / 3600.0, 0) AS dbu_per_hour_per_node FROM system.billing.usage u WHERE u.usage_date >= DATE_SUB(CURRENT_DATE(), 90) AND u.usage_metadata.node_type IS NOT NULL GROUP BY 1 ORDER BY 2 DESC;
B26: Note: system.billing.usage carries the Databricks DBU platform fee only. The underlying cloud VM $/hr is billed separately by AWS/Azure/GCP — pull it from your AWS Cost & Usage Report or Azure Cost Management export if you want that side actualized too; this model keeps VM $/hr at list price.
B29: 3. Paste Results — Effective $/DBU by Workload
B30: Mode | C30: Total DBUs (period) | D30: Total DBU $ (period) | E30: Effective $/DBU
B31: Batch / Triggered | C31: 0 | D31: 0 | E31: =IFERROR(D31/C31,"")
B32: Continuous / Streaming | C32: 0 | D32: 0 | E32: =IFERROR(D32/C32,"")
B34: Leave Total DBUs at 0 to keep using list price for that mode — the Assumptions tab falls back automatically.
B36: 4. Paste Results — DBU/hr by Instance Type
B37: Instance Type | C37: Total DBUs (period) | D37: Total Node-Hours (period) | E37: DBU/hr /node
B38: m5.xlarge (EXAMPLE — overwrite or delete) | C38: 12500 | D38: 18100 | E38: =IFERROR(C38/D38,"") -> 0.69060773
B39: m5.xlarge | C39: 0 | D39: 0 | E39: =IFERROR(C39/D39,"")
B40: m5.2xlarge | C40: 0 | D40: 0 | E40: =IFERROR(C40/D40,"")
B41: r5.4xlarge | C41: 0 | D41: 0 | E41: =IFERROR(C41/D41,"")
B42: r5.8xlarge | C42: 0 | D42: 0 | E42: =IFERROR(C42/D42,"")
B43: Standard_D4ds_v5 | C43: 0 | D43: 0 | E43: =IFERROR(C43/D43,"")
B44: Standard_D8ds_v5 | C44: 0 | D44: 0 | E44: =IFERROR(C44/D44,"")
B45: Standard_D16ds_v5 | C45: 0 | D45: 0 | E45: =IFERROR(C45/D45,"")
B46: Standard_D32ds_v5 | C46: 0 | D46: 0 | E46: =IFERROR(C46/D46,"")
B47: Standard_E4ds_v5 | C47: 0 | D47: 0 | E47: =IFERROR(C47/D47,"")
B48: Standard_E8ds_v5 | C48: 0 | D48: 0 | E48: =IFERROR(C48/D48,"")
B49: Standard_E16ds_v5 | C49: 0 | D49: 0 | E49: =IFERROR(C49/D49,"")
B50: Standard_E32ds_v5 | C50: 0 | D50: 0 | E50: =IFERROR(C50/D50,"")
B52: Instance-type text must match the Assumptions tab exactly (it already does above). Leave a row's Total DBUs at 0 to keep list price for that node type.

Sheet Batch Mode
B2: Batch / Triggered SDP Pipelines — Monthly Cost by Medallion Layer
B3: DBU rate used (from Assumptions §3): | D3: =Assumptions!$D$25 -> 0
B5: Layer | C5: Instance Tier | D5: Node Count | E5: DBU/hr /node | F5: VM $/hr /node | G5: Avg Run Duration (hr) | H5: Runs / Day | I5: Days / Month | J5: DBU Consumed/Mo | K5: DBU Platform Cost/Mo | L5: VM Infra Cost/Mo | M5: Total Cost/Mo
B6: Bronze | C6: Small | D6: 3 | E6: =INDEX(Assumptions!$D$15:$D$18,MATCH($C6,Assumptions!$B$15:$B$18,0)) -> 0.69 | F6: =INDEX(Assumptions!$E$15:$E$18,MATCH($C6,Assumptions!$B$15:$B$18,0)) -> 0.192 | G6: 0.5 | H6: 24 | I6: 30 | J6: =$D6*$E6*$G6*$H6*$I6 -> 745.2 | K6: =$J6*$D$3 -> 0 | L6: =$D6*$F6*$G6*$H6*$I6 -> 207.36 | M6: =$K6+$L6 -> 207.36
B7: Silver | C7: Medium | D7: 4 | E7: =INDEX(Assumptions!$D$15:$D$18,MATCH($C7,Assumptions!$B$15:$B$18,0)) -> 1.38 | F7: =INDEX(Assumptions!$E$15:$E$18,MATCH($C7,Assumptions!$B$15:$B$18,0)) -> 0.384 | G7: 1 | H7: 4 | I7: 30 | J7: =$D7*$E7*$G7*$H7*$I7 -> 662.4 | K7: =$J7*$D$3 -> 0 | L7: =$D7*$F7*$G7*$H7*$I7 -> 184.32 | M7: =$K7+$L7 -> 184.32
B8: Gold | C8: Medium | D8: 3 | E8: =INDEX(Assumptions!$D$15:$D$18,MATCH($C8,Assumptions!$B$15:$B$18,0)) -> 1.38 | F8: =INDEX(Assumptions!$E$15:$E$18,MATCH($C8,Assumptions!$B$15:$B$18,0)) -> 0.384 | G8: 0.75 | H8: 2 | I8: 30 | J8: =$D8*$E8*$G8*$H8*$I8 -> 186.3 | K8: =$J8*$D$3 -> 0 | L8: =$D8*$F8*$G8*$H8*$I8 -> 51.84 | M8: =$K8+$L8 -> 51.84
B9: Total | J9: =SUM(J6:J8) -> 1593.9 | K9: =SUM(K6:K8) -> 0 | L9: =SUM(L6:L8) -> 443.52 | M9: =SUM(M6:M8) -> 443.52
B11: Assumption notes
B12: Bronze: frequent short incremental-ingest runs (hourly) on a small cluster — typical raw-landing pattern.
B13: Silver: fewer, longer transform runs on a medium cluster (dedupe, conform, join, quality checks).
B14: Gold: infrequent, business-aggregation runs feeding BI/reporting — smallest DBU footprint of the three.
B15: Runs/Day, Duration, Node Count and Tier are all blue — replace with your own job-history averages.

Sheet Continuous Mode
B2: Continuous / Always-On SDP Pipelines — Monthly Cost by Medallion Layer
B3: DBU rate used (from Assumptions §3): | D3: =IF($G$3="Continuous (Jobs Compute)",Assumptions!$D$30,Assumptions!$D$29) -> 0.35 | F3: Rate Mode: | G3: SDP Serverless (Standard) | H3: ← pick classic Jobs Compute here to price continuous pipelines without SDP Serverless
B5: Layer | C5: Instance Tier | D5: Node Count (avg) | E5: DBU/hr /node | F5: VM $/hr /node | G5: Avg Utilization % | H5: Hours / Day | I5: Days / Month | J5: DBU Consumed/Mo | K5: DBU Platform Cost/Mo | L5: VM Infra Cost/Mo | M5: Total Cost/Mo
B6: Bronze | C6: Small | D6: 2 | E6: =INDEX(Assumptions!$D$15:$D$18,MATCH($C6,Assumptions!$B$15:$B$18,0)) -> 0.69 | F6: =INDEX(Assumptions!$E$15:$E$18,MATCH($C6,Assumptions!$B$15:$B$18,0)) -> 0.192 | G6: 1 | H6: 24 | I6: 30 | J6: =$D6*$E6*$G6*$H6*$I6 -> 993.6 | K6: =$J6*$D$3 -> 347.76 | L6: =$D6*$F6*$G6*$H6*$I6 -> 276.48 | M6: =$K6+$L6 -> 624.24
B7: Silver | C7: Medium | D7: 3 | E7: =INDEX(Assumptions!$D$15:$D$18,MATCH($C7,Assumptions!$B$15:$B$18,0)) -> 1.38 | F7: =INDEX(Assumptions!$E$15:$E$18,MATCH($C7,Assumptions!$B$15:$B$18,0)) -> 0.384 | G7: 0.9 | H7: 24 | I7: 30 | J7: =$D7*$E7*$G7*$H7*$I7 -> 2682.72 | K7: =$J7*$D$3 -> 938.952 | L7: =$D7*$F7*$G7*$H7*$I7 -> 746.496 | M7: =$K7+$L7 -> 1685.448
B8: Gold | C8: Medium | D8: 2 | E8: =INDEX(Assumptions!$D$15:$D$18,MATCH($C8,Assumptions!$B$15:$B$18,0)) -> 1.38 | F8: =INDEX(Assumptions!$E$15:$E$18,MATCH($C8,Assumptions!$B$15:$B$18,0)) -> 0.384 | G8: 0.7 | H8: 24 | I8: 30 | J8: =$D8*$E8*$G8*$H8*$I8 -> 1391.04 | K8: =$J8*$D$3 -> 486.864 | L8: =$D8*$F8*$G8*$H8*$I8 -> 387.072 | M8: =$K8+$L8 -> 873.936
B9: Total | J9: =SUM(J6:J8) -> 5067.36 | K9: =SUM(K6:K8) -> 1773.576 | L9: =SUM(L6:L8) -> 1410.048 | M9: =SUM(M6:M8) -> 3183.624
B11: Assumption notes
B12: Continuous pipelines use SDP Serverless with enhanced autoscaling — Node Count is the AVERAGE node count
B13: over the month (autoscaler expands/contracts with input rate), not a fixed cluster size.
B14: Utilization % derates 24x7 wall-clock hours to reflect autoscale-to-minimum during low-traffic windows.
B15: Bronze stays near 100% (continuous ingest rarely idles); Gold is lowest since aggregation triggers on
B16: upstream data arrival rather than a constant stream.

Sheet B2S Sizing & Cost
B2: Bronze → Silver Worker Node Recommendation & Cost Impact
B3: Enter your pipeline's actual table size, row count and file profile below — the model sizes and prices the ONE-TIME initial load/backfill separately from the RECURRING delta/incremental load.
B5: 1. Pipeline Characteristics — EDIT THESE (placeholder values shown)
B6: Parameter | C6: Value | D6: Unit / Notes
B7: Bronze table size | C7: 500 | D7: GB — total size of the Bronze table(s) feeding this run
B8: Silver output size | C8: 400 | D8: GB — leave as-is if unknown; defaults to ~80% of Bronze
B9: Row count | C9: 250 | D9: millions of rows
B10: Number of files | C10: 5000 | D10: files in the Bronze source location
B11: New data arrival interval | C11: 30 | D11: minutes — how often a new batch of files lands
B12: Max acceptable staleness (latency SLA) | C12: 60 | D12: minutes — how fresh Silver must be
B13: Delta run target completion window | C13: 20 | D13: minutes — how fast you want each INCREMENTAL (delta) run to finish. Initial load gets its own window below.
B14: Avg file size (computed) | C14: =($C$7*1024)/$C$10 -> 102.4 | D14: MB — Bronze size ÷ file count
B16: 2. File Layout Check
B17: Metric | C17: Value | D17: Notes
B18: Ideal partition size | C18: 128 | D18: MB — standard Spark/Delta target file size
B19: Ideal number of partitions | C19: =CEILING($C$7*1024/$C$18,1) -> 4000
B20: Files ÷ ideal partitions ratio | C20: =$C$10/$C$19 -> 1.25
B21: File layout flag | C21: =IF(OR($C$14<16,$C$20>3),"SMALL FILES","OK") -> OK | D21: =IF(OR($C$14<16,$C$20>3),"Avg file size is small and/or file count far exceeds the ideal partition count — run OPTIMIZE / auto-compaction on Bronze before scaling workers up; extra workers mostly buy you file-open overhead, not throughput.","File sizes and count are in a reasonable range for direct processing.") -> File sizes and count are in a reasonable range for direct processing.
B23: 3. Node Tier Throughput Assumptions (edit if you have real job telemetry)
B24: Tier | C24: Instance Type | D24: vCPUs | E24: GB / hr / node (light transform: parse, dedupe, conform, light joins)
B25: Small | C25: =Assumptions!$C$15 -> m5.xlarge | D25: =Assumptions!$F$15 -> 4 | E25: 15
B26: Medium | C26: =Assumptions!$C$16 -> m5.2xlarge | D26: =Assumptions!$F$16 -> 8 | E26: 40
B27: Large | C27: =Assumptions!$C$17 -> r5.4xlarge | D27: =Assumptions!$F$17 -> 16 | E27: 100
B28: XLarge | C28: =Assumptions!$C$18 -> r5.8xlarge | D28: =Assumptions!$F$18 -> 32 | E28: 200
B29: Instance type and vCPU follow the Cloud/Series selection on the Assumptions tab. GB/hr/node throughput is a general rule of thumb, not a measured figure — tune from your own Spark UI stage timings.
B31: 4. Tier-Selection Thresholds (GB of data to process)
B32: Tier | C32: Use when data volume is… | D32: Threshold (GB)
B33: Small | C33: < 100 GB | D33: 100
B34: Medium | C34: 100–800 GB | D34: 800
B35: Large | C35: 800–3,000 GB | D35: 3000
B36: XLarge | C36: > 3,000 GB
B38: 5. Initial Load / Backfill Sizing — ONE-TIME, full table volume
B39: Metric | C39: Value | D39: Notes
B40: Data volume to process | C40: =MAX($C$7,$C$8) -> 500 | D40: GB — the full Bronze/Silver table, processed once
B41: Initial load target completion window | C41: 4 | D41: hours — backfills can tolerate a longer window than incremental runs
B42: Recommended tier | C42: =IF($C$40<$D$33,"Small",IF($C$40<=$D$34,"Medium",IF($C$40<=$D$35,"Large","XLarge"))) -> Medium
B43: Recommended instance type | C43: =INDEX(Assumptions!$C$15:$C$18,MATCH($C$42,Assumptions!$B$15:$B$18,0)) -> m5.2xlarge | D43: ="vCPU: "&INDEX(Assumptions!$F$15:$F$18,MATCH($C$42,Assumptions!$B$15:$B$18,0))&" | RAM: "&INDEX(Assumptions!$G$15:$G$18,MATCH($C$42,Assumptions!$B$15:$B$18,0))&" GB per node" -> vCPU: 8 | RAM: 32 GB per node
B44: Throughput / node | C44: =INDEX($E$25:$E$28,MATCH($C$42,$B$25:$B$28,0)) -> 40 | D44: GB / hr
B45: Recommended worker count | C45: =MAX(2,CEILING($C$40/($C$44*$C$41),1)) -> 4 | D45: workers (+1 driver), sized to finish the ONE-TIME backfill within the window above
B46: Estimated backfill runtime | C46: =$C$40/($C$44*$C$45) -> 3.125 | D46: hours — single run, start to finish
...

Sheet Pipeline DBU Actuals
B2: Pipeline DBU Actuals — Real Consumption by Pipeline
B3: Paste DBUs consumed per pipeline below (from system.billing.usage — see the costing notebook, query 1.3). Cost is computed automatically from the Assumptions rate table based on the Mode you pick per row.
B5: 1. DBUs Consumed by Pipeline
B6: Pipeline Name | C6: Medallion Layer | D6: Mode | E6: Period (days) | F6: DBUs Consumed | G6: $/DBU (mode rate) | H6: Cost for Period | I6: Monthly Run-Rate | J6: Notes
B7: bronze_ingest_pipeline (EXAMPLE — overwrite or delete) | C7: Bronze | D7: Batch / Triggered | E7: 30 | F7: 18500 | G7: =IFERROR(INDEX(Assumptions!$D$28:$D$30,MATCH(D7,Assumptions!$B$28:$B$30,0)),"") -> 0.15 | H7: =IFERROR(F7*G7,"") -> 2775 | I7: =IFERROR(H7/E7*30,"") -> 2775 | J7: from system.billing.usage, last 30 days
C8: Bronze | D8: Batch / Triggered | E8: 30 | F8: 0 | G8: =IFERROR(INDEX(Assumptions!$D$28:$D$30,MATCH(D8,Assumptions!$B$28:$B$30,0)),"") -> 0.15 | H8: =IFERROR(F8*G8,"") -> 0 | I8: =IFERROR(H8/E8*30,"") -> 0
C9: Bronze | D9: Batch / Triggered | E9: 30 | F9: 0 | G9: =IFERROR(INDEX(Assumptions!$D$28:$D$30,MATCH(D9,Assumptions!$B$28:$B$30,0)),"") -> 0.15 | H9: =IFERROR(F9*G9,"") -> 0 | I9: =IFERROR(H9/E9*30,"") -> 0
C10: Bronze | D10: Batch / Triggered | E10: 30 | F10: 0 | G10: =IFERROR(INDEX(Assumptions!$D$28:$D$30,MATCH(D10,Assumptions!$B$28:$B$30,0)),"") -> 0.15 | H10: =IFERROR(F10*G10,"") -> 0 | I10: =IFERROR(H10/E10*30,"") -> 0
C11: Bronze | D11: Batch / Triggered | E11: 30 | F11: 0 | G11: =IFERROR(INDEX(Assumptions!$D$28:$D$30,MATCH(D11,Assumptions!$B$28:$B$30,0)),"") -> 0.15 | H11: =IFERROR(F11*G11,"") -> 0 | I11: =IFERROR(H11/E11*30,"") -> 0
C12: Bronze | D12: Batch / Triggered | E12: 30 | F12: 0 | G12: =IFERROR(INDEX(Assumptions!$D$28:$D$30,MATCH(D12,Assumptions!$B$28:$B$30,0)),"") -> 0.15 | H12: =IFERROR(F12*G12,"") -> 0 | I12: =IFERROR(H12/E12*30,"") -> 0
C13: Bronze | D13: Batch / Triggered | E13: 30 | F13: 0 | G13: =IFERROR(INDEX(Assumptions!$D$28:$D$30,MATCH(D13,Assumptions!$B$28:$B$30,0)),"") -> 0.15 | H13: =IFERROR(F13*G13,"") -> 0 | I13: =IFERROR(H13/E13*30,"") -> 0
C14: Bronze | D14: Batch / Triggered | E14: 30 | F14: 0 | G14: =IFERROR(INDEX(Assumptions!$D$28:$D$30,MATCH(D14,Assumptions!$B$28:$B$30,0)),"") -> 0.15 | H14: =IFERROR(F14*G14,"") -> 0 | I14: =IFERROR(H14/E14*30,"") -> 0
C15: Bronze | D15: Batch / Triggered | E15: 30 | F15: 0 | G15: =IFERROR(INDEX(Assumptions!$D$28:$D$30,MATCH(D15,Assumptions!$B$28:$B$30,0)),"") -> 0.15 | H15: =IFERROR(F15*G15,"") -> 0 | I15: =IFERROR(H15/E15*30,"") -> 0
C16: Bronze | D16: Batch / Triggered | E16: 30 | F16: 0 | G16: =IFERROR(INDEX(Assumptions!$D$28:$D$30,MATCH(D16,Assumptions!$B$28:$B$30,0)),"") -> 0.15 | H16: =IFERROR(F16*G16,"") -> 0 | I16: =IFERROR(H16/E16*30,"") -> 0
C17: Bronze | D17: Batch / Triggered | E17: 30 | F17: 0 | G17: =IFERROR(INDEX(Assumptions!$D$28:$D$30,MATCH(D17,Assumptions!$B$28:$B$30,0)),"") -> 0.15 | H17: =IFERROR(F17*G17,"") -> 0 | I17: =IFERROR(H17/E17*30,"") -> 0
C18: Bronze | D18: Batch / Triggered | E18: 30 | F18: 0 | G18: =IFERROR(INDEX(Assumptions!$D$28:$D$30,MATCH(D18,Assumptions!$B$28:$B$30,0)),"") -> 0.15 | H18: =IFERROR(F18*G18,"") -> 0 | I18: =IFERROR(H18/E18*30,"") -> 0
C19: Bronze | D19: Batch / Triggered | E19: 30 | F19: 0 | G19: =IFERROR(INDEX(Assumptions!$D$28:$D$30,MATCH(D19,Assumptions!$B$28:$B$30,0)),"") -> 0.15 | H19: =IFERROR(F19*G19,"") -> 0 | I19: =IFERROR(H19/E19*30,"") -> 0
... C21: Bronze | D21: Batch / Triggered | E21: 30 | F21: 0 | G21: =IFERROR(INDEX(Assumptions!$D$28:$D$30,MATCH(D21,Assumptions!$B$28:$B$30,0)),"") -> 0.15 | H21: =IFERROR(F21*G21,"") -> 0 | I21: =IFERROR(H21/E21*30,"") -> 0
B22: Leave Pipeline Name blank to exclude a row from the totals below. ‘Period (days)’ lets the model normalize a 7-day or 90-day pull to a monthly run-rate.
B24: 2. Actual Summary by Medallion Layer
B25: Layer | C25: Total DBUs (period) | D25: Total Cost (period) | E25: Actual Monthly Run-Rate
B26: Bronze | C26: =SUMIFS($F$7:$F$21,$C$7:$C$21,B26,$B$7:$B$21,"<>") -> 18500 | D26: =SUMIFS($H$7:$H$21,$C$7:$C$21,B26,$B$7:$B$21,"<>") -> 2775 | E26: =SUMIFS($I$7:$I$21,$C$7:$C$21,B26,$B$7:$B$21,"<>") -> 2775
B27: Silver | C27: =SUMIFS($F$7:$F$21,$C$7:$C$21,B27,$B$7:$B$21,"<>") -> 0 | D27: =SUMIFS($H$7:$H$21,$C$7:$C$21,B27,$B$7:$B$21,"<>") -> 0 | E27: =SUMIFS($I$7:$I$21,$C$7:$C$21,B27,$B$7:$B$21,"<>") -> 0
B28: Gold | C28: =SUMIFS($F$7:$F$21,$C$7:$C$21,B28,$B$7:$B$21,"<>") -> 0 | D28: =SUMIFS($H$7:$H$21,$C$7:$C$21,B28,$B$7:$B$21,"<>") -> 0 | E28: =SUMIFS($I$7:$I$21,$C$7:$C$21,B28,$B$7:$B$21,"<>") -> 0
B29: Other | C29: =SUMIFS($F$7:$F$21,$C$7:$C$21,B29,$B$7:$B$21,"<>") -> 0 | D29: =SUMIFS($H$7:$H$21,$C$7:$C$21,B29,$B$7:$B$21,"<>") -> 0 | E29: =SUMIFS($I$7:$I$21,$C$7:$C$21,B29,$B$7:$B$21,"<>") -> 0
B30: Total | C30: =SUM(C26:C29) -> 18500 | D30: =SUM(D26:D29) -> 2775 | E30: =SUM(E26:E29) -> 2775
B32: 3. Actual vs. Modeled Monthly Cost
B33: Layer | C33: Actual Monthly Run-Rate | D33: Modeled (Batch Mode) | E33: Modeled (Continuous Mode) | F33: Variance vs Batch | G33: Variance vs Continuous
B34: Bronze | C34: =$E$26 -> 2775 | D34: ='Batch Mode'!$M$6 -> 207.36 | E34: ='Continuous Mode'!$M$6 -> 624.24 | F34: =IF(D34=0,"n/a",C34-D34) -> 2567.64 | G34: =IF(E34=0,"n/a",C34-E34) -> 2150.76
B35: Silver | C35: =$E$27 -> 0 | D35: ='Batch Mode'!$M$7 -> 184.32 | E35: ='Continuous Mode'!$M$7 -> 1685.448 | F35: =IF(D35=0,"n/a",C35-D35) -> -184.32 | G35: =IF(E35=0,"n/a",C35-E35) -> -1685.448
B36: Gold | C36: =$E$28 -> 0 | D36: ='Batch Mode'!$M$8 -> 51.84 | E36: ='Continuous Mode'!$M$8 -> 873.936 | F36: =IF(D36=0,"n/a",C36-D36) -> -51.84 | G36: =IF(E36=0,"n/a",C36-E36) -> -873.936
B37: Total | C37: =SUM(C34:C36) -> 2775 | D37: =SUM(D34:D36) -> 443.52 | E37: =SUM(E34:E36) -> 3183.624 | F37: =C37-D37 -> 2331.48 | G37: =C37-E37 -> -408.624
B38: Positive variance = actual usage is running higher than the model assumed (time to revisit sizing on the Batch Mode / Continuous Mode / B2S tabs); negative = the model is over-provisioned relative to real usage.

Sheet Summary
B2: SDP Medallion Pipeline — Monthly Cost Summary
B4: Layer | C4: Batch Monthly Cost | D4: Continuous Monthly Cost | E4: $ Delta (Cont. − Batch) | F4: Continuous is ___x Batch
B5: Bronze | C5: ='Batch Mode'!$M$6 -> 207.36 | D5: ='Continuous Mode'!$M$6 -> 624.24 | E5: =D5-C5 -> 416.88 | F5: =IF(C5=0,"n/a",D5/C5) -> 3.0104167
B6: Silver | C6: ='Batch Mode'!$M$7 -> 184.32 | D6: ='Continuous Mode'!$M$7 -> 1685.448 | E6: =D6-C6 -> 1501.128 | F6: =IF(C6=0,"n/a",D6/C6) -> 9.1441406
B7: Gold | C7: ='Batch Mode'!$M$8 -> 51.84 | D7: ='Continuous Mode'!$M$8 -> 873.936 | E7: =D7-C7 -> 822.096 | F7: =IF(C7=0,"n/a",D7/C7) -> 16.858333
B8: Total | C8: =SUM(C5:C7) -> 443.52 | D8: =SUM(D5:D7) -> 3183.624 | E8: =D8-C8 -> 2740.104 | F8: =D8/C8 -> 7.1780844
B10: Annualized (x12)
C11: Batch Annual Cost | D11: Continuous Annual Cost | E11: $ Delta / yr
B12: Total | C12: =C8*12 -> 5322.24 | D12: =D8*12 -> 38203.488 | E12: =D12-C12 -> 32881.248
B32: Takeaway
B33: Continuous pipelines cost more per month because they pay for wall-clock uptime instead of task duration — the gap narrows for layers with naturally high, steady data velocity (Bronze ingest) and widens for layers that only need to run periodically (Gold).
